Workbook

Sheet Working Paper
A1: WORKING PAPER — Working Capital & Balance Sheet Movement
A2: Period: [กรอกงวด] Company: Consolidated (CONSO) Prepared by: ___________ Date: ___________
A3: # | B3: Account No. | C3: Account Name | D3: FS Caption | E3: Opening Balance (กรอกต้นงวด) | F3: Closing Balance (จาก TB) | G3: Change (Closing-Opening) | H3: CF Impact (ผลต่อ CF) | I3: CF Activity | J3: IC? | K3: Note / Reference
A4: 1. ลูกหนี้การค้า (Accounts Receivable)
A5: Logic: AR เพิ่ม = ใช้เงินสด = CF ลบ | AR ลด = เก็บเงินได้ = CF บวก | Activity: Operating
C6: Intercompany accounts highlighted in yellow
B7: 11121010 | C7: ลูกหนี้การค้า-กิจการที่ไม่เกี่ยวข้องกัน | D7: ลูกหนี้การค้า | F7: 21637.318 | G7: =F7-E7 | H7: =-G7 | I7: Operating
B8: 11121011 | C8: ลูกหนี้การค้า-ไฟแนนซ์ | D8: ลูกหนี้การค้า | F8: 31829.245 | G8: =F8-E8 | H8: =-G8 | I8: Operating
B9: 11121012 | C9: ลูกหนี้การค้า-ประกันภัย | D9: ลูกหนี้การค้า | F9: 149328.99 | G9: =F9-E9 | H9: =-G9 | I9: Operating
B10: 11121013 | C10: ลูกหนี้การค้า-รถเช่า | D10: ลูกหนี้การค้า | F10: 3953.1866 | G10: =F10-E10 | H10: =-G10 | I10: Operating
B11: 11121014 | C11: ลูกหนี้การค้า-คอเปอร์เรท | D11: ลูกหนี้การค้า | F11: 0 | G11: =F11-E11 | H11: =-G11 | I11: Operating
B12: 11121020 | C12: ลูกหนี้การค้า-ฮอนด้า ออโต้โมบิล | D12: ลูกหนี้การค้า | F12: 37301.63 | G12: =F12-E12 | H12: =-G12 | I12: Operating
B13: 11121099 | C13: ค่าเผื่อหนี้สงสัยจะสูญ | D13: ลูกหนี้การค้า | F13: -29536.03 | G13: =F13-E13 | H13: =-G13 | I13: Operating
C14: รวม 1. ลูกหนี้การค้า (Accounts Receivable) | E14: =SUM(E7:E13) | F14: =SUM(F7:F13) | G14: =SUM(G7:G13) | H14: =SUM(H7:H13) | I14: Operating
A16: 2. ลูกหนี้หมุนเวียนอื่น (Other Current Receivables)
A17: Logic: เพิ่ม = CF ลบ | Activity: Operating
C18: Intercompany accounts highlighted in yellow
B19: 11141010 | C19: ลูกหนี้เงินทดรอง-พนักงาน | D19: ลูกหนี้หมุนเวียนอื่น | F19: 2155.94 | G19: =F19-E19 | H19: =-G19 | I19: Operating
B20: 11151010 | C20: ลูกหนี้อื่น | D20: ลูกหนี้หมุนเวียนอื่น | F20: 7484.8206 | G20: =F20-E20 | H20: =-G20 | I20: Operating
B21: 11151035 | C21: ลูกหนี้เงิน-พนักงาน | D21: ลูกหนี้หมุนเวียนอื่น | F21: 46.1319 | G21: =F21-E21 | H21: =-G21 | I21: Operating
B22: 11151011 | C22: ค่าใช้จ่ายจ่ายล่วงหน้า | D22: ลูกหนี้หมุนเวียนอื่น | F22: 38542.029 | G22: =F22-E22 | H22: =-G22 | I22: Operating
B23: 11151015 | C23: ภาษีเงินได้ถูกหัก ณ ที่จ่าย | D23: สินทรัพย์ภาษีเงินได้ของงวดปัจจุบัน | F23: 6404.3739 | G23: =F23-E23 | H23: =-G23 | I23: Operating
B24: 11151017 | C24: รายได้ค้างรับ-ค่านายหน้าไฟแนนซ์ | D24: ลูกหนี้หมุนเวียนอื่น | F24: 1258.1504 | G24: =F24-E24 | H24: =-G24 | I24: Operating
B25: 11151018 | C25: รายได้ค้างรับ-ค่านายหน้าประกันภัย | D25: ลูกหนี้หมุนเวียนอื่น | F25: 3348.5612 | G25: =F25-E25 | H25: =-G25 | I25: Operating
B26: 11151019 | C26: รายได้ค้างรับ-ค่าแรงเคลมฮอนด้า | D26: ลูกหนี้หมุนเวียนอื่น | F26: 1835.9 | G26: =F26-E26 | H26: =-G26 | I26: Operating
B27: 11151020 | C27: รายได้ค้างรับ-อะไหล่เคลมฮอนด้า | D27: ลูกหนี้หมุนเวียนอื่น | F27: 16800.906 | G27: =F27-E27 | H27: =-G27 | I27: Operating
B28: 11151023 | C28: รายได้ค้างรับ-รางวัลการขาย | D28: ลูกหนี้หมุนเวียนอื่น | F28: 55906.995 | G28: =F28-E28 | H28: =-G28 | I28: Operating
B29: 11151028 | C29: รายได้ค้างรับ-ค่าแรงเคลม-คุณภาพ | D29: ลูกหนี้หมุนเวียนอื่น | F29: 3951.8503 | G29: =F29-E29 | H29: =-G29 | I29: Operating
B30: 11151029 | C30: รายได้ค้างรับ-ค่าแรงเคลม-Exclusive | D30: ลูกหนี้หมุนเวียนอื่น | F30: 2383.7 | G30: =F30-E30 | H30: =-G30 | I30: Operating
... B37: 11151012-1 | C37: ลูกหนี้กรมสรรพากร | D37: ลูกหนี้หมุนเวียนอื่น | F37: 48554.327 | G37: =F37-E37 | H37: =-G37 | I37: Operating
B38: 11121030 | C38: ลูกหนี้การค้า-กิจการที่เกี่ยวข้องกัน | D38: ลูกหนี้หมุนเวียนอื่น | F38: 0 | G38: =F38-E38 | H38: =-G38 | I38: Operating | J38: IC
B39: 11141020 | C39: ลูกหนี้เงินทดรอง-อื่น | D39: ลูกหนี้หมุนเวียนอื่น | F39: 1.1641532e-12 | G39: =F39-E39 | H39: =-G39 | I39: Operating
B40: 11141030 | C40: ลูกหนี้เงินทดรอง-กิจการที่เกี่ยวข้องกัน | D40: ลูกหนี้หมุนเวียนอื่น | F40: 0 | G40: =F40-E40 | H40: =-G40 | I40: Operating | J40: IC
B41: 11151021 | C41: เงินปันผลค้างรับ | D41: ลูกหนี้หมุนเวียนอื่น | F41: 0 | G41: =F41-E41 | H41: =-G41 | I41: Operating
B42: 11151024 | C42: contra ภาษีมูลค่าเพิ่ม | D42: ลูกหนี้หมุนเวียนอื่น | F42: 0 | G42: =F42-E42 | H42: =-G42 | I42: Operating
B43: 11151025 | C43: ลูกหนี้อื่น-กิจการที่เกี่ยวข้องกัน | D43: ลูกหนี้หมุนเวียนอื่น | F43: 0 | G43: =F43-E43 | H43: =-G43 | I43: Operating | J43: IC
B44: 11151026 | C44: รายได้ค้างรับบริการซ่อม | D44: ลูกหนี้หมุนเวียนอื่น | F44: 0 | G44: =F44-E44 | H44: =-G44 | I44: Operating
B45: 11212011 | C45: ดอกเบี้ยค้างรับจากบริษัทย่อย | D45: ลูกหนี้หมุนเวียนอื่น | F45: 0 | G45: =F45-E45 | H45: =-G45 | I45: Operating | J45: IC
B46: 11212031 | C46: ดอกเบี้ยค้างรับจากบริษัทอื่น | D46: ลูกหนี้หมุนเวียนอื่น | F46: 0 | G46: =F46-E46 | H46: =-G46 | I46: Operating
C47: รวม 2. ลูกหนี้หมุนเวียนอื่น (Other Current Receivables) | E47: =SUM(E19:E46) | F47: =SUM(F19:F46) | G47: =SUM(G19:G46) | H47: =SUM(H19:H46) | I47: Operating
...

Sheet CF Summary (WC)
A1: สรุปผลกระทบ Working Capital ต่อ Cash Flow Statement (Indirect Method)
A2: รายการ | B2: CF Impact (บาท) | C2: Activity
A3: 1. ลูกหนี้การค้า (Accounts Receivable) | B3: ='Working Paper'!H14 | C3: Operating
A4: 2. ลูกหนี้หมุนเวียนอื่น (Other Current Receivables) | B4: ='Working Paper'!H47 | C4: Operating
A5: 3. ที่ดิน อาคาร อุปกรณ์ / PPE & Investment Property | B5: ='Working Paper'!H76 | C5: Investing
A6: 4. สินทรัพย์สิทธิการใช้ ROU Asset (TFRS 16) | B6: ดูรายละเอียด | C6: Operating (add-back)
A7: 5. สินทรัพย์ภาษีเงินได้รอตัดบัญชี / สินทรัพย์อื่น | B7: ='Working Paper'!H93 | C7: Investing
A8: 6. เจ้าหนี้การค้า (Accounts Payable) | B8: ='Working Paper'!H105 | C8: Operating
A9: 7. เจ้าหนี้หมุนเวียนอื่น / ค่าใช้จ่ายค้างจ่าย / ดอกเบี้ยค้างจ่าย | B9: ='Working Paper'!H147 | C9: Operating
A10: 8. หนี้สินตามสัญญาเช่า Lease Liability (TFRS 16) | B10: ดูรายละเอียด | C10: Financing
A11: 9. เงินกู้ยืมจากสถาบันการเงิน (Bank Loans) | B11: ='Working Paper'!H163 | C11: Financing
A12: 10. ประมาณการผลประโยชน์พนักงาน (Employee Benefit) | B12: ='Working Paper'!H170 | C12: Operating (add-back)
A13: 11. ภาษีเงินได้นิติบุคคลค้างจ่าย (Income Tax Payable) | B13: ='Working Paper'!H176 | C13: Operating
A14: 12. หนี้สินภาษีเงินได้รอตัดบัญชี / หนี้สินไม่หมุนเวียนอื่น | B14: ='Working Paper'!H183 | C14: Operating / Financing
A16: รวมผลกระทบ — Operating Activities | B16: =SUM(B3,B4,B6,B8,B9,B12,B13,B14)
A17: รวมผลกระทบ — Investing Activities | B17: =SUM(B5,B7)
A18: รวมผลกระทบ — Financing Activities | B18: =SUM(B10,B11)
A20: หมายเหตุ: ตัวเลขสีน้ำเงินใน Working Paper = กรอกเอง (Opening Balance) | สีเขียว = จาก TB | เซลล์สีเหลือง = Intercompany (IC) — ถูก Eliminate ใน CONSO

Sheet Instructions
A1: วิธีใช้ Working Paper Template นี้
A3: STEP 1 — กรอก Opening Balance (คอลัมน์ E สีน้ำเงิน)
A4: กรอกยอดยกมาต้นงวด (เช่น 31 Dec 2023) สำหรับทุก Account
A5: ถ้ามี TB งวดก่อนหน้า สามารถ paste ค่าตรงๆ ได้เลย
A7: STEP 2 — ตรวจสอบ Closing Balance (คอลัมน์ F สีเขียว)
A8: คอลัมน์ F ดึงมาจาก TB ที่ให้มา (CONSO) โดยอัตโนมัติ
A9: ถ้าตัวเลขไม่ตรงกับ TB ให้แจ้งทีม Accounting
A11: STEP 3 — ระบบคำนวณ Change และ CF Impact ให้อัตโนมัติ
A12: Change = Closing - Opening (คอลัมน์ G)
A13: CF Impact = Change * Sign (คอลัมน์ H) — ดูสูตรแต่ละ Section
A15: STEP 4 — ดูสรุปใน Sheet "CF Summary (WC)"
A16: Sheet นี้รวม CF Impact แยกตาม Operating / Investing / Financing
... A31: ให้ขอ TFRS 16 Schedule จากฝ่ายบัญชีเพิ่มเติม
